<?xml version="1.0"?>
<robot xmlns:xacro="http://ros.org/wiki/xacro">

  <xacro:include filename="$(find scanner_description)/urdf/model/lidar_body/scanner_lidar_body.gazebo.xacro"/>
  
  <xacro:macro name="scanner_lidar_body" params="parent color *joint_origin *joint_axis *joint_limit">
    <joint name="lidar_body_joint" type="revolute">
      <xacro:insert_block name="joint_origin"/>
      <xacro:insert_block name="joint_axis"/>
      <xacro:insert_block name="joint_limit"/>
      <parent link="${parent}"/>
      <child link="lidar_body"/>
        
    </joint>

    <link name="lidar_body">
      <visual>
        <origin xyz="0 0 0" rpy="0 0 0"/>
        <geometry><box size="0.05 0.05 0.05"/></geometry>
        <material name="${color}"/>
      </visual>
      <collision>
        <origin xyz="0 0 0" rpy="0 0 0"/>
        <geometry><box size="0.05 0.05 0.05"/></geometry>
      </collision>
      <inertial>
        <mass value="0.1"/>
        <origin xyz="0 0 0"/>
        <inertia ixx="0.1" ixy="0.0" ixz="0.0" iyy="0.1" iyz="0.0" izz="0.1"/>
      </inertial>
    </link>

  </xacro:macro>
  
</robot>
